Workbook

Sheet Apresentação
A1: Projeto de Gestão Administrativa | Central de Controles
A3: PROJETO SIMULADO PARA PORTFÓLIO — dados e empresa fictícios, criados para demonstrar competências administrativas.
A5: Cenário | B5: Uma empresa fictícia precisa centralizar rotinas administrativas que antes eram acompanhadas separadamente.
A6: Objetivo | B6: Criar uma central de gestão para acompanhar solicitações internas, documentos, notas fiscais, fornecedores, reuniões e prazos.
A7: Ferramentas | B7: Excel | estrutura compatível com rotinas administrativas
A8: Período simulado | B8: Julho a setembro de 2026
A9: Módulos | B9: Solicitações | Documentos | Notas Fiscais | Fornecedores | Agenda | Dashboard
A10: Indicadores | B10: Demandas por status e prioridade, atrasos, documentos próximos do vencimento, notas pendentes, fornecedores ativos e compromissos.
A11: Competências | B11: Organização, atenção aos detalhes, planejamento, gestão do tempo, Excel intermediário e acompanhamento de prazos.
A12: Diferencial | B12: Projeto integrado: várias rotinas administrativas em um único controle.
A13: Status | B13: Concluído
A14: Observação | B14: Não representa experiência profissional em empresa real.

Sheet Solicitações
A1: Controle de Solicitações Internas
O2: Data de referência | P2: 46289
A3: ID | B3: Data Abertura | C3: Setor | D3: Tipo de Solicitação | E3: Descrição | F3: Responsável | G3: Prioridade | H3: Prazo | I3: Status | J3: Data Conclusão | K3: Dias em Aberto | L3: Atrasada? | M3: Observação
A4: ADM-001 | B4: 46265 | C4: Operações | D4: Cadastro/atualização | E4: Demanda administrativa simulada | F4: Carla Mendes | G4: Baixa | H4: 46277 | I4: Pendente | K4: =IF(J4<>"",J4-B4,$P$2-B4) -> 24 | L4: =IF(AND(I4<>"Concluída",$P$2>H4),"Sim",IF(AND(I4="Concluída",J4>H4),"Sim","Não")) -> Sim | M4: Projeto de portfólio
A5: ADM-002 | B5: 46212 | C5: Comercial | D5: Reembolso | E5: Demanda administrativa simulada | F5: Diego Alves | G5: Baixa | H5: 46224 | I5: Pendente | K5: =IF(J5<>"",J5-B5,$P$2-B5) -> 77 | L5: =IF(AND(I5<>"Concluída",$P$2>H5),"Sim",IF(AND(I5="Concluída",J5>H5),"Sim","Não")) -> Sim | M5: Projeto de portfólio
A6: ADM-003 | B6: 46287 | C6: Comercial | D6: Apoio administrativo | E6: Demanda administrativa simulada | F6: Bruno Souza | G6: Baixa | H6: 46299 | I6: Concluída | J6: 46295 | K6: =IF(J6<>"",J6-B6,$P$2-B6) -> 8 | L6: =IF(AND(I6<>"Concluída",$P$2>H6),"Sim",IF(AND(I6="Concluída",J6>H6),"Sim","Não")) -> Não | M6: Projeto de portfólio
A7: ADM-004 | B7: 46227 | C7: Comercial | D7: Acesso a sistema | E7: Demanda administrativa simulada | F7: Carla Mendes | G7: Baixa | H7: 46239 | I7: Concluída | J7: 46229 | K7: =IF(J7<>"",J7-B7,$P$2-B7) -> 2 | L7: =IF(AND(I7<>"Concluída",$P$2>H7),"Sim",IF(AND(I7="Concluída",J7>H7),"Sim","Não")) -> Não | M7: Projeto de portfólio
A8: ADM-005 | B8: 46226 | C8: Diretoria | D8: Acesso a sistema | E8: Demanda administrativa simulada | F8: Ana Lima | G8: Baixa | H8: 46238 | I8: Concluída | J8: 46228 | K8: =IF(J8<>"",J8-B8,$P$2-B8) -> 2 | L8: =IF(AND(I8<>"Concluída",$P$2>H8),"Sim",IF(AND(I8="Concluída",J8>H8),"Sim","Não")) -> Não | M8: Projeto de portfólio
A9: ADM-006 | B9: 46227 | C9: TI | D9: Agendamento | E9: Demanda administrativa simulada | F9: Carla Mendes | G9: Média | H9: 46234 | I9: Concluída | J9: 46239 | K9: =IF(J9<>"",J9-B9,$P$2-B9) -> 12 | L9: =IF(AND(I9<>"Concluída",$P$2>H9),"Sim",IF(AND(I9="Concluída",J9>H9),"Sim","Não")) -> Sim | M9: Projeto de portfólio
A10: ADM-007 | B10: 46267 | C10: Operações | D10: Relatório | E10: Demanda administrativa simulada | F10: Bruno Souza | G10: Média | H10: 46274 | I10: Concluída | J10: 46270 | K10: =IF(J10<>"",J10-B10,$P$2-B10) -> 3 | L10: =IF(AND(I10<>"Concluída",$P$2>H10),"Sim",IF(AND(I10="Concluída",J10>H10),"Sim","Não")) -> Não | M10: Projeto de portfólio
A11: ADM-008 | B11: 46235 | C11: RH | D11: Compra de material | E11: Demanda administrativa simulada | F11: Carla Mendes | G11: Baixa | H11: 46247 | I11: Concluída | J11: 46244 | K11: =IF(J11<>"",J11-B11,$P$2-B11) -> 9 | L11: =IF(AND(I11<>"Concluída",$P$2>H11),"Sim",IF(AND(I11="Concluída",J11>H11),"Sim","Não")) -> Não | M11: Projeto de portfólio
A12: ADM-009 | B12: 46238 | C12: Comercial | D12: Apoio administrativo | E12: Demanda administrativa simulada | F12: Diego Alves | G12: Alta | H12: 46242 | I12: Concluída | J12: 46249 | K12: =IF(J12<>"",J12-B12,$P$2-B12) -> 11 | L12: =IF(AND(I12<>"Concluída",$P$2>H12),"Sim",IF(AND(I12="Concluída",J12>H12),"Sim","Não")) -> Sim | M12: Projeto de portfólio
A13: ADM-010 | B13: 46231 | C13: Comercial | D13: Reembolso | E13: Demanda administrativa simulada | F13: Diego Alves | G13: Média | H13: 46238 | I13: Concluída | J13: 46240 | K13: =IF(J13<>"",J13-B13,$P$2-B13) -> 9 | L13: =IF(AND(I13<>"Concluída",$P$2>H13),"Sim",IF(AND(I13="Concluída",J13>H13),"Sim","Não")) -> Sim | M13: Projeto de portfólio
A14: ADM-011 | B14: 46288 | C14: Diretoria | D14: Acesso a sistema | E14: Demanda administrativa simulada | F14: Ana Lima | G14: Média | H14: 46295 | I14: Concluída | J14: 46289 | K14: =IF(J14<>"",J14-B14,$P$2-B14) -> 1 | L14: =IF(AND(I14<>"Concluída",$P$2>H14),"Sim",IF(AND(I14="Concluída",J14>H14),"Sim","Não")) -> Não | M14: Projeto de portfólio
A15: ADM-012 | B15: 46216 | C15: Operações | D15: Apoio administrativo | E15: Demanda administrativa simulada | F15: Bruno Souza | G15: Média | H15: 46223 | I15: Em andamento | K15: =IF(J15<>"",J15-B15,$P$2-B15) -> 73 | L15: =IF(AND(I15<>"Concluída",$P$2>H15),"Sim",IF(AND(I15="Concluída",J15>H15),"Sim","Não")) -> Sim | M15: Projeto de portfólio
A16: ADM-013 | B16: 46274 | C16: Diretoria | D16: Reembolso | E16: Demanda administrativa simulada | F16: Ana Lima | G16: Alta | H16: 46278 | I16: Concluída | J16: 46276 | K16: =IF(J16<>"",J16-B16,$P$2-B16) -> 2 | L16: =IF(AND(I16<>"Concluída",$P$2>H16),"Sim",IF(AND(I16="Concluída",J16>H16),"Sim","Não")) -> Não | M16: Projeto de portfólio
A17: ADM-014 | B17: 46251 | C17: Diretoria | D17: Cadastro/atualização | E17: Demanda administrativa simulada | F17: Ana Lima | G17: Baixa | H17: 46263 | I17: Concluída | J17: 46254 | K17: =IF(J17<>"",J17-B17,$P$2-B17) -> 3 | L17: =IF(AND(I17<>"Concluída",$P$2>H17),"Sim",IF(AND(I17="Concluída",J17>H17),"Sim","Não")) -> Não | M17: Projeto de portfólio
A18: ADM-015 | B18: 46273 | C18: Financeiro | D18: Acesso a sistema | E18: Demanda administrativa simulada | F18: Diego Alves | G18: Média | H18: 46280 | I18: Concluída | J18: 46278 | K18: =IF(J18<>"",J18-B18,$P$2-B18) -> 5 | L18: =IF(AND(I18<>"Concluída",$P$2>H18),"Sim",IF(AND(I18="Concluída",J18>H18),"Sim","Não")) -> Não | M18: Projeto de portfólio
A19: ADM-016 | B19: 46204 | C19: Comercial | D19: Agendamento | E19: Demanda administrativa simulada | F19: Ana Lima | G19: Média | H19: 46211 | I19: Concluída | J19: 46206 | K19: =IF(J19<>"",J19-B19,$P$2-B19) -> 2 | L19: =IF(AND(I19<>"Concluída",$P$2>H19),"Sim",IF(AND(I19="Concluída",J19>H19),"Sim","Não")) -> Não | M19: Projeto de portfólio
A20: ADM-017 | B20: 46241 | C20: Diretoria | D20: Compra de material | E20: Demanda administrativa simulada | F20: Ana Lima | G20: Alta | H20: 46245 | I20: Concluída | J20: 46246 | K20: =IF(J20<>"",J20-B20,$P$2-B20) -> 5 | L20: =IF(AND(I20<>"Concluída",$P$2>H20),"Sim",IF(AND(I20="Concluída",J20>H20),"Sim","Não")) -> Sim | M20: Projeto de portfólio
A21: ADM-018 | B21: 46281 | C21: Diretoria | D21: Acesso a sistema | E21: Demanda administrativa simulada | F21: Carla Mendes | G21: Média | H21: 46288 | I21: Concluída | J21: 46292 | K21: =IF(J21<>"",J21-B21,$P$2-B21) -> 11 | L21: =IF(AND(I21<>"Concluída",$P$2>H21),"Sim",IF(AND(I21="Concluída",J21>H21),"Sim","Não")) -> Sim | M21: Projeto de portfólio
A22: ADM-019 | B22: 46219 | C22: Comercial | D22: Cadastro/atualização | E22: Demanda administrativa simulada | F22: Ana Lima | G22: Média | H22: 46226 | I22: Em andamento | K22: =IF(J22<>"",J22-B22,$P$2-B22) -> 70 | L22: =IF(AND(I22<>"Concluída",$P$2>H22),"Sim",IF(AND(I22="Concluída",J22>H22),"Sim","Não")) -> Sim | M22: Projeto de portfólio
A23: ADM-020 | B23: 46228 | C23: Comercial | D23: Reembolso | E23: Demanda administrativa simulada | F23: Ana Lima | G23: Alta | H23: 46232 | I23: Pendente | K23: =IF(J23<>"",J23-B23,$P$2-B23) -> 61 | L23: =IF(AND(I23<>"Concluída",$P$2>H23),"Sim",IF(AND(I23="Concluída",J23>H23),"Sim","Não")) -> Sim | M23: Projeto de portfólio
A24: ADM-021 | B24: 46248 | C24: Operações | D24: Relatório | E24: Demanda administrativa simulada | F24: Carla Mendes | G24: Média | H24: 46255 | I24: Concluída | J24: 46259 | K24: =IF(J24<>"",J24-B24,$P$2-B24) -> 11 | L24: =IF(AND(I24<>"Concluída",$P$2>H24),"Sim",IF(AND(I24="Concluída",J24>H24),"Sim","Não")) -> Sim | M24: Projeto de portfólio
A25: ADM-022 | B25: 46272 | C25: Financeiro | D25: Reembolso | E25: Demanda administrativa simulada | F25: Carla Mendes | G25: Média | H25: 46279 | I25: Em andamento | K25: =IF(J25<>"",J25-B25,$P$2-B25) -> 17 | L25: =IF(AND(I25<>"Concluída",$P$2>H25),"Sim",IF(AND(I25="Concluída",J25>H25),"Sim","Não")) -> Sim | M25: Projeto de portfólio
A26: ADM-023 | B26: 46255 | C26: Comercial | D26: Compra de material | E26: Demanda administrativa simulada | F26: Diego Alves | G26: Baixa | H26: 46267 | I26: Em andamento | K26: =IF(J26<>"",J26-B26,$P$2-B26) -> 34 | L26: =IF(AND(I26<>"Concluída",$P$2>H26),"Sim",IF(AND(I26="Concluída",J26>H26),"Sim","Não")) -> Sim | M26: Projeto de portfólio
A27: ADM-024 | B27: 46256 | C27: Comercial | D27: Relatório | E27: Demanda administrativa simulada | F27: Carla Mendes | G27: Baixa | H27: 46268 | I27: Em andamento | K27: =IF(J27<>"",J27-B27,$P$2-B27) -> 33 | L27: =IF(AND(I27<>"Concluída",$P$2>H27),"Sim",IF(AND(I27="Concluída",J27>H27),"Sim","Não")) -> Sim | M27: Projeto de portfólio
A28: ADM-025 | B28: 46237 | C28: RH | D28: Documento | E28: Demanda administrativa simulada | F28: Diego Alves | G28: Média | H28: 46244 | I28: Concluída | J28: 46243 | K28: =IF(J28<>"",J28-B28,$P$2-B28) -> 6 | L28: =IF(AND(I28<>"Concluída",$P$2>H28),"Sim",IF(AND(I28="Concluída",J28>H28),"Sim","Não")) -> Não | M28: Projeto de portfólio
A29: ADM-026 | B29: 46260 | C29: Operações | D29: Documento | E29: Demanda administrativa simulada | F29: Ana Lima | G29: Média | H29: 46267 | I29: Concluída | J29: 46263 | K29: =IF(J29<>"",J29-B29,$P$2-B29) -> 3 | L29: =IF(AND(I29<>"Concluída",$P$2>H29),"Sim",IF(AND(I29="Concluída",J29>H29),"Sim","Não")) -> Não | M29: Projeto de portfólio
A30: ADM-027 | B30: 46284 | C30: TI | D30: Apoio administrativo | E30: Demanda administrativa simulada | F30: Diego Alves | G30: Média | H30: 46291 | I30: Concluída | J30: 46294 | K30: =IF(J30<>"",J30-B30,$P$2-B30) -> 10 | L30: =IF(AND(I30<>"Concluída",$P$2>H30),"Sim",IF(AND(I30="Concluída",J30>H30),"Sim","Não")) -> Sim | M30: Projeto de portfólio
A31: ADM-028 | B31: 46288 | C31: RH | D31: Relatório | E31: Demanda administrativa simulada | F31: Ana Lima | G31: Baixa | H31: 46300 | I31: Concluída | J31: 46295 | K31: =IF(J31<>"",J31-B31,$P$2-B31) -> 7 | L31: =IF(AND(I31<>"Concluída",$P$2>H31),"Sim",IF(AND(I31="Concluída",J31>H31),"Sim","Não")) -> Não | M31: Projeto de portfólio
A32: ADM-029 | B32: 46232 | C32: Comercial | D32: Reembolso | E32: Demanda administrativa simulada | F32: Ana Lima | G32: Baixa | H32: 46244 | I32: Em andamento | K32: =IF(J32<>"",J32-B32,$P$2-B32) -> 57 | L32: =IF(AND(I32<>"Concluída",$P$2>H32),"Sim",IF(AND(I32="Concluída",J32>H32),"Sim","Não")) -> Sim | M32: Projeto de portfólio
A33: ADM-030 | B33: 46210 | C33: Financeiro | D33: Cadastro/atualização | E33: Demanda administrativa simulada | F33: Ana Lima | G33: Média | H33: 46217 | I33: Em andamento | K33: =IF(J33<>"",J33-B33,$P$2-B33) -> 79 | L33: =IF(AND(I33<>"Concluída",$P$2>H33),"Sim",IF(AND(I33="Concluída",J33>H33),"Sim","Não")) -> Sim | M33: Projeto de portfólio
A34: ADM-031 | B34: 46215 | C34: Comercial | D34: Apoio administrativo | E34: Demanda administrativa simulada | F34: Bruno Souza | G34: Alta | H34: 46219 | I34: Concluída | J34: 46224 | K34: =IF(J34<>"",J34-B34,$P$2-B34) -> 9 | L34: =IF(AND(I34<>"Concluída",$P$2>H34),"Sim",IF(AND(I34="Concluída",J34>H34),"Sim","Não")) -> Sim | M34: Projeto de portfólio
A35: ADM-032 | B35: 46262 | C35: RH | D35: Relatório | E35: Demanda administrativa simulada | F35: Ana Lima | G35: Média | H35: 46269 | I35: Em andamento | K35: =IF(J35<>"",J35-B35,$P$2-B35) -> 27 | L35: =IF(AND(I35<>"Concluída",$P$2>H35),"Sim",IF(AND(I35="Concluída",J35>H35),"Sim","Não")) -> Sim | M35: Projeto de portfólio
A36: ADM-033 | B36: 46221 | C36: Operações | D36: Cadastro/atualização | E36: Demanda administrativa simulada | F36: Ana Lima | G36: Média | H36: 46228 | I36: Concluída | J36: 46227 | K36: =IF(J36<>"",J36-B36,$P$2-B36) -> 6 | L36: =IF(AND(I36<>"Concluída",$P$2>H36),"Sim",IF(AND(I36="Concluída",J36>H36),"Sim","Não")) -> Não | M36: Projeto de portfólio
A37: ADM-034 | B37: 46233 | C37: Comercial | D37: Agendamento | E37: Demanda administrativa simulada | F37: Diego Alves | G37: Baixa | H37: 46245 | I37: Em andamento | K37: =IF(J37<>"",J37-B37,$P$2-B37) -> 56 | L37: =IF(AND(I37<>"Concluída",$P$2>H37),"Sim",IF(AND(I37="Concluída",J37>H37),"Sim","Não")) -> Sim | M37: Projeto de portfólio
A38: ADM-035 | B38: 46283 | C38: TI | D38: Cadastro/atualização | E38: Demanda administrativa simulada | F38: Carla Mendes | G38: Baixa | H38: 46295 | I38: Concluída | J38: 46291 | K38: =IF(J38<>"",J38-B38,$P$2-B38) -> 8 | L38: =IF(AND(I38<>"Concluída",$P$2>H38),"Sim",IF(AND(I38="Concluída",J38>H38),"Sim","Não")) -> Não | M38: Projeto de portfólio
A39: ADM-036 | B39: 46248 | C39: Financeiro | D39: Apoio administrativo | E39: Demanda administrativa simulada | F39: Diego Alves | G39: Alta | H39: 46252 | I39: Concluída | J39: 46258 | K39: =IF(J39<>"",J39-B39,$P$2-B39) -> 10 | L39: =IF(AND(I39<>"Concluída",$P$2>H39),"Sim",IF(AND(I39="Concluída",J39>H39),"Sim","Não")) -> Sim | M39: Projeto de portfólio
A40: ADM-037 | B40: 46261 | C40: RH | D40: Reembolso | E40: Demanda administrativa simulada | F40: Diego Alves | G40: Média | H40: 46268 | I40: Concluída | J40: 46264 | K40: =IF(J40<>"",J40-B40,$P$2-B40) -> 3 | L40: =IF(AND(I40<>"Concluída",$P$2>H40),"Sim",IF(AND(I40="Concluída",J40>H40),"Sim","Não")) -> Não | M40: Projeto de portfólio
...

Sheet Documentos
A1: Controle de Documentos Administrativos | L1: Parâmetro | M1: Valor
L2: Data de referência | M2: 46289
A3: Código | B3: Documento | C3: Categoria | D3: Responsável | E3: Data Emissão | F3: Validade | G3: Dias p/ Vencer | H3: Situação | I3: Local/Referência | J3: Observação
A4: DOC-001 | B4: Contrato fornecedor | C4: Interno | D4: Bruno Souza | E4: 46101 | F4: 46466 | G4: =F4-$M$2 -> 177 | H4: =IF(G4<0,"Vencido",IF(G4<=30,"Vence em até 30 dias","Regular")) -> Regular | I4: Pasta Digital/Contratos | J4: Documento simulado
A5: DOC-002 | B5: Certidão | C5: Contratos | D5: Bruno Souza | E5: 46085 | F5: 46815 | G5: =F5-$M$2 -> 526 | H5: =IF(G5<0,"Vencido",IF(G5<=30,"Vence em até 30 dias","Regular")) -> Regular | I5: Pasta Digital/Interno | J5: Documento simulado
A6: DOC-003 | B6: Licença | C6: Fiscal | D6: Bruno Souza | E6: 46164 | F6: 46529 | G6: =F6-$M$2 -> 240 | H6: =IF(G6<0,"Vencido",IF(G6<=30,"Vence em até 30 dias","Regular")) -> Regular | I6: Pasta Digital/Interno | J6: Documento simulado
A7: DOC-004 | B7: Apólice | C7: Fornecedores | D7: Diego Alves | E7: 46202 | F7: 46472 | G7: =F7-$M$2 -> 183 | H7: =IF(G7<0,"Vencido",IF(G7<=30,"Vence em até 30 dias","Regular")) -> Regular | I7: Pasta Digital/Fiscal | J7: Documento simulado
A8: DOC-005 | B8: Contrato de serviço | C8: Legal | D8: Carla Mendes | E8: 46193 | F8: 46558 | G8: =F8-$M$2 -> 269 | H8: =IF(G8<0,"Vencido",IF(G8<=30,"Vence em até 30 dias","Regular")) -> Regular | I8: Pasta Digital/Interno | J8: Documento simulado
A9: DOC-006 | B9: Cadastro fornecedor | C9: Contratos | D9: Diego Alves | E9: 46067 | F9: 46432 | G9: =F9-$M$2 -> 143 | H9: =IF(G9<0,"Vencido",IF(G9<=30,"Vence em até 30 dias","Regular")) -> Regular | I9: Pasta Digital/Interno | J9: Documento simulado
A10: DOC-007 | B10: Termo interno | C10: Fornecedores | D10: Diego Alves | E10: 46166 | F10: 46346 | G10: =F10-$M$2 -> 57 | H10: =IF(G10<0,"Vencido",IF(G10<=30,"Vence em até 30 dias","Regular")) -> Regular | I10: Pasta Digital/Legal | J10: Documento simulado
A11: DOC-008 | B11: Procuração | C11: Legal | D11: Ana Lima | E11: 46031 | F11: 46301 | G11: =F11-$M$2 -> 12 | H11: =IF(G11<0,"Vencido",IF(G11<=30,"Vence em até 30 dias","Regular")) -> Vence em até 30 dias | I11: Pasta Digital/Fiscal | J11: Documento simulado
A12: DOC-009 | B12: Documento societário | C12: Fornecedores | D12: Diego Alves | E12: 46119 | F12: 46484 | G12: =F12-$M$2 -> 195 | H12: =IF(G12<0,"Vencido",IF(G12<=30,"Vence em até 30 dias","Regular")) -> Regular | I12: Pasta Digital/Legal | J12: Documento simulado
A13: DOC-010 | B13: Comprovante cadastral | C13: Interno | D13: Diego Alves | E13: 46184 | F13: 46454 | G13: =F13-$M$2 -> 165 | H13: =IF(G13<0,"Vencido",IF(G13<=30,"Vence em até 30 dias","Regular")) -> Regular | I13: Pasta Digital/Legal | J13: Documento simulado
A14: DOC-011 | B14: Contrato locação | C14: Fornecedores | D14: Carla Mendes | E14: 46175 | F14: 46905 | G14: =F14-$M$2 -> 616 | H14: =IF(G14<0,"Vencido",IF(G14<=30,"Vence em até 30 dias","Regular")) -> Regular | I14: Pasta Digital/Fiscal | J14: Documento simulado
A15: DOC-012 | B15: Certificado | C15: Fornecedores | D15: Ana Lima | E15: 46045 | F15: 46315 | G15: =F15-$M$2 -> 26 | H15: =IF(G15<0,"Vencido",IF(G15<=30,"Vence em até 30 dias","Regular")) -> Vence em até 30 dias | I15: Pasta Digital/Interno | J15: Documento simulado

Sheet Notas Fiscais
A1: Controle de Notas Fiscais | N1: Parâmetro | O1: Valor
N2: Data de referência | O2: 46289
A3: NF | B3: Data Emissão | C3: Fornecedor | D3: Categoria | E3: Valor | F3: Centro de Custo | G3: Vencimento | H3: Conferida? | I3: Status Pagamento | J3: Data Pagamento | K3: Dias até Vencimento | L3: Observação
A4: NF-2400 | B4: 46224 | C4: Alfa Suprimentos | D4: Marketing | E4: 2551.53 | F4: Financeiro | G4: 46244 | H4: Sim | I4: Pago | J4: 46243 | K4: =G4-$O$2 -> -45 | L4: Nota simulada
A5: NF-2401 | B5: 46217 | C5: Nova Mídia | D5: Marketing | E5: 2078.15 | F5: Financeiro | G5: 46237 | H5: Sim | I5: Pago | J5: 46233 | K5: =G5-$O$2 -> -52 | L5: Nota simulada
A6: NF-2402 | B6: 46237 | C6: Beta Serviços | D6: Serviço | E6: 3335.74 | F6: TI | G6: 46257 | H6: Sim | I6: Pago | J6: 46256 | K6: =G6-$O$2 -> -32 | L6: Nota simulada
A7: NF-2403 | B7: 46257 | C7: Beta Serviços | D7: Material | E7: 7596.42 | F7: Operações | G7: 46277 | H7: Sim | I7: Pendente | K7: =G7-$O$2 -> -12 | L7: Nota simulada
A8: NF-2404 | B8: 46273 | C8: Office Mais | D8: Serviço | E8: 4112.21 | F8: Financeiro | G8: 46288 | H8: Sim | I8: Pago | J8: 46288 | K8: =G8-$O$2 -> -1 | L8: Nota simulada
A9: NF-2405 | B9: 46229 | C9: Data Solutions | D9: Material | E9: 4739.81 | F9: Financeiro | G9: 46249 | H9: Não | I9: Pago | J9: 46248 | K9: =G9-$O$2 -> -40 | L9: Nota simulada
A10: NF-2406 | B10: 46208 | C10: Connect TI | D10: Serviço | E10: 3975.98 | F10: TI | G10: 46228 | H10: Sim | I10: Pago | J10: 46228 | K10: =G10-$O$2 -> -61 | L10: Nota simulada
A11: NF-2407 | B11: 46222 | C11: Alfa Suprimentos | D11: Material | E11: 4800.32 | F11: Operações | G11: 46237 | H11: Sim | I11: Pendente | K11: =G11-$O$2 -> -52 | L11: Nota simulada
A12: NF-2408 | B12: 46269 | C12: Log Express | D12: Serviço | E12: 7700.31 | F12: Operações | G12: 46289 | H12: Não | I12: Pago | J12: 46285 | K12: =G12-$O$2 -> 0 | L12: Nota simulada
A13: NF-2409 | B13: 46258 | C13: Data Solutions | D13: Marketing | E13: 7746.7 | F13: Operações | G13: 46288 | H13: Sim | I13: Pago | J13: 46287 | K13: =G13-$O$2 -> -1 | L13: Nota simulada
A14: NF-2410 | B14: 46237 | C14: Office Mais | D14: Logística | E14: 6352.33 | F14: TI | G14: 46252 | H14: Sim | I14: Pendente | K14: =G14-$O$2 -> -37 | L14: Nota simulada
A15: NF-2411 | B15: 46239 | C15: Data Solutions | D15: Marketing | E15: 1365.6 | F15: Financeiro | G15: 46254 | H15: Não | I15: Pendente | K15: =G15-$O$2 -> -35 | L15: Nota simulada
A16: NF-2412 | B16: 46242 | C16: Log Express | D16: Marketing | E16: 499.18 | F16: Financeiro | G16: 46257 | H16: Sim | I16: Pago | J16: 46257 | K16: =G16-$O$2 -> -32 | L16: Nota simulada
A17: NF-2413 | B17: 46223 | C17: Nova Mídia | D17: Serviço | E17: 371.02 | F17: Operações | G17: 46243 | H17: Não | I17: Pago | J17: 46240 | K17: =G17-$O$2 -> -46 | L17: Nota simulada
A18: NF-2414 | B18: 46258 | C18: Office Mais | D18: Marketing | E18: 5515.74 | F18: Comercial | G18: 46273 | H18: Não | I18: Pago | J18: 46270 | K18: =G18-$O$2 -> -16 | L18: Nota simulada
A19: NF-2415 | B19: 46214 | C19: Connect TI | D19: Material | E19: 1832.2 | F19: Diretoria | G19: 46229 | H19: Sim | I19: Pago | J19: 46229 | K19: =G19-$O$2 -> -60 | L19: Nota simulada
A20: NF-2416 | B20: 46222 | C20: Alfa Suprimentos | D20: Marketing | E20: 6042.84 | F20: Diretoria | G20: 46242 | H20: Sim | I20: Pago | J20: 46238 | K20: =G20-$O$2 -> -47 | L20: Nota simulada
A21: NF-2417 | B21: 46231 | C21: Prime Facilities | D21: Logística | E21: 3110.33 | F21: Operações | G21: 46251 | H21: Sim | I21: Pago | J21: 46249 | K21: =G21-$O$2 -> -38 | L21: Nota simulada
A22: NF-2418 | B22: 46277 | C22: Log Express | D22: Tecnologia | E22: 2314.24 | F22: RH | G22: 46307 | H22: Sim | I22: Pendente | K22: =G22-$O$2 -> 18 | L22: Nota simulada
A23: NF-2419 | B23: 46279 | C23: Alfa Suprimentos | D23: Tecnologia | E23: 7797.16 | F23: Diretoria | G23: 46309 | H23: Sim | I23: Pago | J23: 46306 | K23: =G23-$O$2 -> 20 | L23: Nota simulada
A24: NF-2420 | B24: 46209 | C24: Beta Serviços | D24: Logística | E24: 3824.74 | F24: TI | G24: 46239 | H24: Sim | I24: Pendente | K24: =G24-$O$2 -> -50 | L24: Nota simulada
A25: NF-2421 | B25: 46288 | C25: Data Solutions | D25: Material | E25: 6385.34 | F25: Diretoria | G25: 46318 | H25: Sim | I25: Pendente | K25: =G25-$O$2 -> 29 | L25: Nota simulada
A26: NF-2422 | B26: 46253 | C26: Office Mais | D26: Material | E26: 3029.52 | F26: RH | G26: 46273 | H26: Sim | I26: Pendente | K26: =G26-$O$2 -> -16 | L26: Nota simulada
A27: NF-2423 | B27: 46208 | C27: Prime Facilities | D27: Marketing | E27: 7760.86 | F27: TI | G27: 46228 | H27: Sim | I27: Pendente | K27: =G27-$O$2 -> -61 | L27: Nota simulada
A28: NF-2424 | B28: 46212 | C28: Nova Mídia | D28: Marketing | E28: 5700.95 | F28: Comercial | G28: 46227 | H28: Não | I28: Pendente | K28: =G28-$O$2 -> -62 | L28: Nota simulada
A29: NF-2425 | B29: 46234 | C29: Beta Serviços | D29: Tecnologia | E29: 3484.29 | F29: Operações | G29: 46254 | H29: Não | I29: Pago | J29: 46253 | K29: =G29-$O$2 -> -35 | L29: Nota simulada
A30: NF-2426 | B30: 46223 | C30: Log Express | D30: Logística | E30: 8745.16 | F30: Diretoria | G30: 46238 | H30: Sim | I30: Pago | J30: 46234 | K30: =G30-$O$2 -> -51 | L30: Nota simulada
A31: NF-2427 | B31: 46252 | C31: Prime Facilities | D31: Marketing | E31: 7439.8 | F31: RH | G31: 46267 | H31: Não | I31: Pago | J31: 46267 | K31: =G31-$O$2 -> -22 | L31: Nota simulada
A32: NF-2428 | B32: 46206 | C32: Beta Serviços | D32: Marketing | E32: 4844.5 | F32: TI | G32: 46236 | H32: Sim | I32: Pago | J32: 46235 | K32: =G32-$O$2 -> -53 | L32: Nota simulada
A33: NF-2429 | B33: 46216 | C33: Office Mais | D33: Material | E33: 8577.56 | F33: RH | G33: 46246 | H33: Sim | I33: Pago | J33: 46246 | K33: =G33-$O$2 -> -43 | L33: Nota simulada
A34: NF-2430 | B34: 46280 | C34: Prime Facilities | D34: Tecnologia | E34: 4410.39 | F34: Diretoria | G34: 46300 | H34: Sim | I34: Pago | J34: 46300 | K34: =G34-$O$2 -> 11 | L34: Nota simulada
A35: NF-2431 | B35: 46216 | C35: Nova Mídia | D35: Material | E35: 1162.38 | F35: RH | G35: 46236 | H35: Não | I35: Pago | J35: 46235 | K35: =G35-$O$2 -> -53 | L35: Nota simulada
A36: NF-2432 | B36: 46242 | C36: Prime Facilities | D36: Marketing | E36: 1671.87 | F36: Comercial | G36: 46257 | H36: Não | I36: Pago | J36: 46255 | K36: =G36-$O$2 -> -32 | L36: Nota simulada
A37: NF-2433 | B37: 46226 | C37: Log Express | D37: Tecnologia | E37: 6162.17 | F37: Diretoria | G37: 46256 | H37: Sim | I37: Pago | J37: 46252 | K37: =G37-$O$2 -> -33 | L37: Nota simulada
A38: NF-2434 | B38: 46286 | C38: Prime Facilities | D38: Marketing | E38: 8003.23 | F38: Comercial | G38: 46306 | H38: Sim | I38: Pago | J38: 46305 | K38: =G38-$O$2 -> 17 | L38: Nota simulada

Sheet Fornecedores
A1: Cadastro e Avaliação de Fornecedores
A3: Código | B3: Fornecedor | C3: Categoria | D3: Contato | E3: E-mail | F3: Prazo Médio (dias) | G3: Qualidade (1-5) | H3: Pontualidade (1-5) | I3: Avaliação Média | J3: Status | K3: Observação
A4: FOR-001 | B4: Alfa Suprimentos | C4: Serviço | D4: (21) 95442-3456 | E4: contato@alfasuprimentos.example | F4: 8 | G4: 5 | H4: 3 | I4: =IFERROR((G4+H4)/2,0) -> 4 | J4: Ativo | K4: Dados fictícios
A5: FOR-002 | B5: Beta Serviços | C5: Material | D5: (21) 99162-6934 | E5: contato@betaserviços.example | F5: 10 | G5: 4 | H5: 5 | I5: =IFERROR((G5+H5)/2,0) -> 4.5 | J5: Ativo | K5: Dados fictícios
A6: FOR-003 | B6: Connect TI | C6: Serviço | D6: (21) 93911-4694 | E6: contato@connectti.example | F6: 3 | G6: 5 | H6: 4 | I6: =IFERROR((G6+H6)/2,0) -> 4.5 | J6: Ativo | K6: Dados fictícios
A7: FOR-004 | B7: Log Express | C7: Material | D7: (21) 93417-7129 | E7: contato@logexpress.example | F7: 4 | G7: 4 | H7: 5 | I7: =IFERROR((G7+H7)/2,0) -> 4.5 | J7: Ativo | K7: Dados fictícios
A8: FOR-005 | B8: Office Mais | C8: Marketing | D8: (21) 96793-9576 | E8: contato@officemais.example | F8: 3 | G8: 5 | H8: 5 | I8: =IFERROR((G8+H8)/2,0) -> 5 | J8: Ativo | K8: Dados fictícios
A9: FOR-006 | B9: Prime Facilities | C9: Serviço | D9: (21) 93372-7415 | E9: contato@primefacilities.example | F9: 8 | G9: 3 | H9: 5 | I9: =IFERROR((G9+H9)/2,0) -> 4 | J9: Ativo | K9: Dados fictícios
A10: FOR-007 | B10: Nova Mídia | C10: Tecnologia | D10: (21) 92929-9608 | E10: contato@novamídia.example | F10: 3 | G10: 5 | H10: 3 | I10: =IFERROR((G10+H10)/2,0) -> 4 | J10: Ativo | K10: Dados fictícios
A11: FOR-008 | B11: Data Solutions | C11: Material | D11: (21) 95155-1303 | E11: contato@datasolutions.example | F11: 10 | G11: 3 | H11: 3 | I11: =IFERROR((G11+H11)/2,0) -> 3 | J11: Ativo | K11: Dados fictícios

Sheet Agenda
A1: Agenda Administrativa e Prazos
A3: ID | B3: Data | C3: Horário | D3: Tipo | E3: Assunto | F3: Responsável | G3: Participantes/Área | H3: Status | I3: Prioridade | J3: Observação
A4: AG-001 | B4: 46297 | C4: 14:00 | D4: Conferência | E4: Conferência de NF | F4: Carla Mendes | G4: Operações | H4: Agendado | I4: Média | J4: Compromisso simulado
A5: AG-002 | B5: 46273 | C5: 09:00 | D5: Reunião | E5: Renovação documental | F5: Carla Mendes | G5: Comercial | H5: Concluído | I5: Alta | J5: Compromisso simulado
A6: AG-003 | B6: 46285 | C6: 09:00 | D6: Follow-up | E6: Renovação documental | F6: Diego Alves | G6: Diretoria | H6: Agendado | I6: Baixa | J6: Compromisso simulado
A7: AG-004 | B7: 46269 | C7: 16:00 | D7: Follow-up | E7: Atualização de relatório | F7: Diego Alves | G7: Operações | H7: Concluído | I7: Média | J7: Compromisso simulado
A8: AG-005 | B8: 46286 | C8: 09:00 | D8: Conferência | E8: Follow-up fornecedor | F8: Carla Mendes | G8: Comercial | H8: Concluído | I8: Média | J8: Compromisso simulado
A9: AG-006 | B9: 46300 | C9: 10:30 | D9: Follow-up | E9: Conferência de NF | F9: Bruno Souza | G9: Comercial | H9: Concluído | I9: Baixa | J9: Compromisso simulado
A10: AG-007 | B10: 46302 | C10: 15:30 | D10: Entrega | E10: Conferência de NF | F10: Carla Mendes | G10: RH | H10: Concluído | I10: Média | J10: Compromisso simulado
A11: AG-008 | B11: 46289 | C11: 16:00 | D11: Entrega | E11: Atualização de relatório | F11: Ana Lima | G11: Diretoria | H11: Agendado | I11: Baixa | J11: Compromisso simulado
A12: AG-009 | B12: 46305 | C12: 09:00 | D12: Conferência | E12: Atualização de relatório | F12: Bruno Souza | G12: Financeiro | H12: Agendado | I12: Alta | J12: Compromisso simulado
A13: AG-010 | B13: 46305 | C13: 15:30 | D13: Reunião | E13: Follow-up fornecedor | F13: Diego Alves | G13: Operações | H13: Concluído | I13: Média | J13: Compromisso simulado
A14: AG-011 | B14: 46289 | C14: 09:00 | D14: Prazo | E14: Fechamento de pendências | F14: Bruno Souza | G14: Financeiro | H14: Concluído | I14: Média | J14: Compromisso simulado
A15: AG-012 | B15: 46306 | C15: 10:30 | D15: Entrega | E15: Follow-up fornecedor | F15: Carla Mendes | G15: RH | H15: Agendado | I15: Média | J15: Compromisso simulado
... A28: AG-025 | B28: 46290 | C28: 14:00 | D28: Prazo | E28: Reunião de alinhamento | F28: Ana Lima | G28: TI | H28: Concluído | I28: Média | J28: Compromisso simulado

Sheet Dashboard
A1: Dashboard | Gestão Administrativa
A3: Visão integrada de demandas, documentos, notas fiscais, fornecedores e agenda — Projeto simulado
A5: Solicitações | B5: =COUNTA(Solicitações!A4:A48) -> 45 | D5: Solicitações Atrasadas | E5: =COUNTIF(Solicitações!L4:L48,"Sim") -> 26 | G5: Taxa de Conclusão | H5: =IFERROR(COUNTIF(Solicitações!I4:I48,"Concluída")/B5,0) -> 0.64444444 | J5: Docs. em Atenção | K5: =COUNTIF(Documentos!H4:H15,"Vencido")+COUNTIF(Documentos!H4:H15,"Vence em até 30 dias") -> 2 | M5: NFs Pendentes | N5: =COUNTIF('Notas Fiscais'!I4:I38,"Pendente") -> 10
A8: Valor NFs Pendentes | B8: =SUMIF('Notas Fiscais'!I4:I38,"Pendente",'Notas Fiscais'!E4:E38) -> 49130.32 | D8: Fornecedores Ativos | E8: =COUNTIF(Fornecedores!J4:J11,"Ativo") -> 8 | G8: Agenda em Aberto | H8: =COUNTIF(Agenda!H4:H28,"Agendado")+COUNTIF(Agenda!H4:H28,"Reagendado") -> 10 | J8: Alta Prioridade | K8: =COUNTIF(Solicitações!G4:G48,"Alta") -> 9 | M8: NFs Não Conferidas | N8: =COUNTIF('Notas Fiscais'!H4:H38,"Não") -> 10
A12: Solicitações por Setor | B12: Qtd | D12: Status Solicitações | E12: Qtd
A13: Financeiro | B13: =COUNTIF(Solicitações!$C$4:$C$48,A13) -> 5 | D13: Concluída | E13: =COUNTIF(Solicitações!$I$4:$I$48,D13) -> 29
A14: RH | B14: =COUNTIF(Solicitações!$C$4:$C$48,A14) -> 7 | D14: Em andamento | E14: =COUNTIF(Solicitações!$I$4:$I$48,D14) -> 13
A15: Comercial | B15: =COUNTIF(Solicitações!$C$4:$C$48,A15) -> 15 | D15: Pendente | E15: =COUNTIF(Solicitações!$I$4:$I$48,D15) -> 3
A16: Operações | B16: =COUNTIF(Solicitações!$C$4:$C$48,A16) -> 8
A17: TI | B17: =COUNTIF(Solicitações!$C$4:$C$48,A17) -> 4
A18: Diretoria | B18: =COUNTIF(Solicitações!$C$4:$C$48,A18) -> 6
A21: Status NF | B21: Qtd
A22: Pago | B22: =COUNTIF('Notas Fiscais'!$I$4:$I$38,"Pago") -> 25
A23: Pendente | B23: =COUNTIF('Notas Fiscais'!$I$4:$I$38,"Pendente") -> 10
A24: Conferida - Sim | B24: =COUNTIF('Notas Fiscais'!$H$4:$H$38,"Sim") -> 25
A25: Conferida - Não | B25: =COUNTIF('Notas Fiscais'!$H$4:$H$38,"Não") -> 10

Sheet Procedimentos
A1: Procedimentos Administrativos Propostos
A3: Rotina | B3: Procedimento | C3: Frequência | D3: Responsável | E3: Controle | F3: Risco Reduzido | G3: Indicador
A4: Solicitações internas | B4: Registrar toda demanda, responsável, prioridade e prazo antes do acompanhamento. | C4: Diária | D4: Assistente Administrativo | E4: Planilha de Solicitações | F4: Perda de prazo | G4: % concluídas / atrasadas
A5: Documentos | B5: Revisar documentos com vencimento próximo e atualizar situação. | C5: Semanal | D5: Assistente Administrativo | E5: Controle de Documentos | F5: Documento vencido | G5: Docs. em atenção
A6: Notas fiscais | B6: Conferir fornecedor, valor, vencimento e status antes do encaminhamento. | C6: Diária | D6: Assistente Administrativo | E6: Controle de NF | F6: Erro ou atraso | G6: NFs pendentes/não conferidas
A7: Fornecedores | B7: Manter cadastro atualizado e registrar avaliação de prazo e qualidade. | C7: Mensal | D7: Administrativo | E7: Cadastro de Fornecedores | F7: Fornecedor inadequado | G7: Avaliação média
A8: Agenda | B8: Consolidar reuniões, prazos e follow-ups em um único calendário. | C8: Diária | D8: Assistente Administrativo | E8: Agenda Administrativa | F8: Esquecimento de compromissos | G8: Agenda em aberto
A9: Fechamento | B9: Revisar pendências e indicadores para priorizar a semana seguinte. | C9: Semanal | D9: Administrativo | E9: Dashboard | F9: Acúmulo de pendências | G9: Atrasos e prioridades

Sheet Portfólio
A1: Texto para o Portfólio | Gestão Administrativa
A3: Campo | B3: Conteúdo
A4: Título | B4: Projeto de Gestão Administrativa — Central de Controles
A5: Contexto | B5: Projeto simulado desenvolvido para centralizar e acompanhar diferentes rotinas de um setor administrativo.
A6: Objetivo | B6: Criar uma estrutura integrada para gestão de solicitações internas, documentos, notas fiscais, fornecedores, compromissos e prazos.
A7: Ferramentas | B7: Excel
A8: Etapas | B8: Definição das rotinas; criação das bases; padronização de status e prioridades; fórmulas para prazos; controles de vencimento; indicadores; dashboard; procedimentos administrativos.
A9: Competências demonstradas | B9: Organização, atenção aos detalhes, Excel intermediário, planejamento, gestão do tempo, acompanhamento de prazos e visão integrada de rotinas administrativas.
A10: Entregas | B10: Cinco controles administrativos, dashboard integrado, indicadores e procedimentos padronizados.
A11: Observação | B11: Dados totalmente simulados para portfólio; não representa experiência em empresa real.
